<?xml version="1.0" ?>
<robot name="turtlebot3_myAGV" xmlns:xacro="http://ros.org/wiki/xacro">
  <xacro:include filename="$(find turtlebot3_description)/urdf/common_properties.xacro"/>
  <xacro:include filename="$(find turtlebot3_description)/urdf/turtlebot3_myAGV.gazebo.xacro"/>

  <link name="base_footprint"/>

  <joint name="base_joint" type="fixed">
    <parent link="base_footprint"/>
    <child link="base_link"/>
    <origin xyz="0 0.0 0.0" rpy="0 0 0"/>
  </joint>
<link
    name="base_link">
    <inertial>
      <origin
        xyz="0 0.000827450108183816 0.0940655414330139"
        rpy="0 0 0" />
      <mass
        value="8.2573504e-01" />
      <inertia
        ixx="2.2124416e-03" ixy="-1.2294101e-05" ixz="3.4938785e-05"
               iyy="2.1193702e-03" iyz="-5.0120904e-06"
               izz="2.0064271e-03" />
    </inertial>
    <visual>
      <origin
        xyz="0 0 0"
        rpy="0 0 0" />
      <geometry>
        <mesh
          filename="package://turtlebot3_agv/meshes/base_link.STL" />
      </geometry>
      <material
        name="">
        <color
          rgba="0.898039215686275 0.917647058823529 0.929411764705882 1" />
      </material>
    </visual>
    <collision>
      <origin
        xyz="0 0 0"
        rpy="0 0 0" />
      <geometry>
        <mesh
          filename="package://turtlebot3_agv/meshes/base_link.STL" />
      </geometry>
    </collision>
  </link>
  <link
    name="wheel_right_link">
    <inertial>
      <origin
        xyz="1.42869155533853E-07 5.01976036182839E-08 0.0126479412682328"
        rpy="0 0 0" />
      <mass
        value="0.314315912620171" />
      <inertia
        ixx="1.1175580e-05" ixy="-4.2369783e-11" ixz="-5.9381719e-09"
               iyy="1.1192413e-05" iyz="-1.4400107e-11"
               izz="2.0712558e-05" />
    </inertial>
    <visual>
      <origin
        xyz="0 0 0"
        rpy="0 0 0" />
      <geometry>
        <mesh
          filename="package://turtlebot3_agv/meshes/Wheel_right_link.STL" />
      </geometry>
      <material
        name="">
        <color
          rgba="0.796078431372549 0.823529411764706 0.937254901960784 1" />
      </material>
    </visual>
    <collision>
      <origin
        xyz="0 0 0"
        rpy="0 0 0" />
      <geometry>
        <mesh
          filename="package://turtlebot3_agv/meshes/Wheel_right_link.STL" />
      </geometry>
    </collision>
  </link>
  <joint
    name="wheel_right_joint"
    type="continuous">
    <origin
      xyz="0 -0.144850779034482 0"
      rpy="-1.5707963267949 0 0" />
    <parent
      link="base_link" />
    <child
      link="wheel_right_link" />
    <axis
      xyz="0 0 1" />
  </joint>
  <link
    name="wheel_left_link">
    <inertial>
      <origin
        xyz="1.48512857914285E-07 -2.95859081029821E-08 -0.0126479412682294"
        rpy="0 0 0" />
      <mass
        value="0.314315912620173" />
      <inertia
        ixx="1.1175580e-05" ixy="-4.2369783e-11" ixz="-5.9381719e-09"
               iyy="1.1192413e-05" iyz="-1.4400107e-11"
               izz="2.0712558e-05" />
    </inertial>
    <visual>
      <origin
        xyz="0 0 0"
        rpy="0 0 0" />
      <geometry>
        <mesh
          filename="package://turtlebot3_agv/meshes/Wheel_left_link.STL" />
      </geometry>
      <material
        name="">
        <color
          rgba="0.796078431372549 0.823529411764706 0.937254901960784 1" />
      </material>
    </visual>
    <collision>
      <origin
        xyz="0 0 0"
        rpy="0 0 0" />
      <geometry>
        <mesh
          filename="package://turtlebot3_agv/meshes/Wheel_left_link.STL" />
      </geometry>
    </collision>
  </link>
  <joint
    name="wheel_left_joint"
    type="continuous">
    <origin
      xyz="0 0.144850779034479 0"
      rpy="-1.5707963267949 0 0" />
    <parent
      link="base_link" />
    <child
      link="wheel_left_link" />
    <axis
      xyz="0 0 1" />
  </joint>
  <link
    name="caster_back_left_link">
    <inertial>
      <origin
        xyz="0.0238758097582441 0.046525963467403 0.00243393414299073"
         />
      <mass
        value="0.005" />
      <inertia
        ixx="0.001" ixy="0.0" ixz="0.0"
               iyy="0.001" iyz="0.0"
               izz="0.001" />
    </inertial>
    <visual>
      <origin
        xyz="0 0 0"
        rpy="0 0 0" />
      <geometry>
        <mesh
          filename="package://turtlebot3_agv/meshes/Wheel_small_1_link.STL" />
      </geometry>
      <material
        name="">
        <color
          rgba="0.752941176470588 0.752941176470588 0.752941176470588 1" />
      </material>
    </visual>
    <collision>
      <origin
        xyz="0 0 0"
        rpy="0 0 0" />
      <geometry>
        <mesh
          filename="package://turtlebot3_agv/meshes/Wheel_small_1_link.STL" />
      </geometry>
    </collision>
  </link>
  <joint
    name="caster_back_left_joint"
    type="fixed">
    <origin
      xyz="0.324561380831399 0.1153 0.022292142743223"
      rpy="-1.5707963267949 0 0" />
    <parent
      link="base_link" />
    <child
      link="caster_back_left_link" />
    <axis
      xyz="0 0 0" />
  </joint>
  <link
    name="caster_back_right_link">
    <inertial>
      <origin
        xyz="0.0239966492860011 0.0465259605815261 0.000372265052759346"
        rpy="0 0 0" />
      <mass
        value="0.005" />
      <inertia
        ixx="0.001" ixy="0.0" ixz="0.0"
               iyy="0.001" iyz="0.0"
               izz="0.001" />
    </inertial>
    <visual>
      <origin
        xyz="0 0 0"
        rpy="0 0 0" />
      <geometry>
        <mesh
          filename="package://turtlebot3_agv/meshes/Wheel_small_2_link.STL" />
      </geometry>
      <material
        name="">
        <color
          rgba="0.752941176470588 0.752941176470588 0.752941176470588 1" />
      </material>
    </visual>
    <collision>
      <origin
        xyz="0 0 0"
        rpy="0 0 0" />
      <geometry>
        <mesh
          filename="package://turtlebot3_agv/meshes/Wheel_small_2_link.STL" />
      </geometry>
    </collision>
  </link>
  <joint
    name="caster_back_right_joint"
    type="fixed">
    <origin
      xyz="0.322061380831399 -0.1153 0.0222921427432125"
      rpy="-1.5707963267949 0 0" />
    <parent
      link="base_link" />
    <child
      link="caster_back_right_link" />
    <axis
      xyz="0 0 0" />
  </joint>
  <joint name="imu_joint" type="fixed">
    <parent link="base_link"/>
    <child link="imu_link"/>
    <origin xyz="-0.032 0 0.068" rpy="0 0 0"/>
  </joint>

  <link name="imu_link"/>

   <joint name="scan_joint" type="fixed">
    <parent link="base_link"/>
    <child link="base_scan"/>
    <origin xyz="0.392242528010143 -0.000156533163617606 0.0793945220729009" rpy="0 0 0"/>
  </joint>

  <link name="base_scan">
    <visual>
      <origin xyz="0 0 0" rpy="0 0 0"/>
      <geometry>
        <mesh filename="package://turtlebot3_agv/meshes/Base_scan.STL"/>
      </geometry>
      <material name="dark"/>
    </visual>

    <collision>
      <origin xyz="0.015 0 -0.0065" rpy="0 0 0"/>
      <geometry>
        <cylinder length="0.0315" radius="0.055"/>
      </geometry>
    </collision>

    <inertial>
      <mass value="0.114" />
      <origin xyz="0 0 0" />
      <inertia ixx="0.001" ixy="0.0" ixz="0.0"
               iyy="0.001" iyz="0.0"
               izz="0.001" />
    </inertial>
  </link>
</robot>

<!-- 
	package://turtlebot3_agv/meshes/Base_scan.STL 
     xyz="0.311063005668211 0.013163320764055 -0.00541146067445972"
!-->
